<?xml version="1.0"?>
<robot name="g1_23dof">
    
    <!-- Materials -->
    <material name="grey">
        <color rgba="0.7 0.7 0.7 1"/>
    </material>
    <material name="dark_grey">
        <color rgba="0.2 0.2 0.2 1"/>
    </material>

    <!-- Base Link (Pelvis) -->
    <link name="pelvis">
        <inertial>
            <origin xyz="0 0 -0.07605" rpy="0 0 0"/>
            <mass value="3.813"/>
            <inertia ixx="0.010549" ixy="0" ixz="0" iyy="0.0093089" iyz="0" izz="0.0079184"/>
        </inertial>
        <visual>
            <geometry>
                <mesh filename="./meshes/pelvis.STL"/>
            </geometry>
            <material name="dark_grey"/>
        </visual>
        <visual>
            <geometry>
                <mesh filename="./meshes/pelvis_contour_link.STL"/>
            </geometry>
            <material name="grey"/>
        </visual>
        <collision>
            <geometry>
                <mesh filename="./meshes/pelvis_contour_link.STL"/>
            </geometry>
        </collision>
    </link>

    <!-- Left Leg -->
    <joint name="left_hip_pitch_joint" type="revolute">
        <parent link="pelvis"/>
        <child link="left_hip_pitch_link"/>
        <origin xyz="0 0.064452 -0.1027" rpy="0 0 0"/>
        <axis xyz="0 1 0"/>
        <limit lower="-2.5307" upper="2.8798" effort="88" velocity="1"/>
        <dynamics damping="0.05" friction="0.2"/>
    </joint>

    <link name="left_hip_pitch_link">
        <inertial>
            <origin xyz="0.002741 0.047791 -0.02606" rpy="0 0 0"/>
            <mass value="1.35"/>
            <inertia ixx="0.00181517" ixy="0" ixz="0" iyy="0.00153422" iyz="0" izz="0.00116212"/>
        </inertial>
        <visual>
            <geometry>
                <mesh filename="./meshes/left_hip_pitch_link.STL"/>
            </geometry>
            <material name="dark_grey"/>
        </visual>
        <collision>
            <geometry>
                <mesh filename="./meshes/left_hip_pitch_link.STL"/>
            </geometry>
        </collision>
    </link>

    <joint name="left_hip_roll_joint" type="revolute">
        <parent link="left_hip_pitch_link"/>
        <child link="left_hip_roll_link"/>
        <origin xyz="0 0.052 -0.030465" rpy="0 -0.0873386 0"/>
        <axis xyz="1 0 0"/>
        <limit lower="-0.5236" upper="2.9671" effort="88" velocity="1"/>
        <dynamics damping="0.05" friction="0.2"/>
    </joint>

    <link name="left_hip_roll_link">
        <inertial>
            <origin xyz="0.029812 -0.001045 -0.087934" rpy="0 0 0"/>
            <mass value="1.52"/>
            <inertia ixx="0.00254986" ixy="0" ixz="0" iyy="0.00241169" iyz="0" izz="0.00148755"/>
        </inertial>
        <visual>
            <geometry>
                <mesh filename="./meshes/left_hip_roll_link.STL"/>
            </geometry>
            <material name="grey"/>
        </visual>
        <collision>
            <geometry>
                <mesh filename="./meshes/left_hip_roll_link.STL"/>
            </geometry>
        </collision>
    </link>

    <joint name="left_hip_yaw_joint" type="revolute">
        <parent link="left_hip_roll_link"/>
        <child link="left_hip_yaw_link"/>
        <origin xyz="0.025001 0 -0.12412" rpy="0 0 0"/>
        <axis xyz="0 0 1"/>
        <limit lower="-2.7576" upper="2.7576" effort="88" velocity="1"/>
        <dynamics damping="0.05" friction="0.2"/>
    </joint>

    <link name="left_hip_yaw_link">
        <inertial>
            <origin xyz="-0.057709 -0.010981 -0.15078" rpy="0 0 0"/>
            <mass value="1.702"/>
            <inertia ixx="0.00776166" ixy="0" ixz="0" iyy="0.00717575" iyz="0" izz="0.00160139"/>
        </inertial>
        <visual>
            <geometry>
                <mesh filename="./meshes/left_hip_yaw_link.STL"/>
            </geometry>
            <material name="grey"/>
        </visual>
        <collision>
            <geometry>
                <mesh filename="./meshes/left_hip_yaw_link.STL"/>
            </geometry>
        </collision>
    </link>

    <joint name="left_knee_joint" type="revolute">
        <parent link="left_hip_yaw_link"/>
        <child link="left_knee_link"/>
        <origin xyz="-0.078273 0.0021489 -0.17734" rpy="0 0.0873386 0"/>
        <axis xyz="0 1 0"/>
        <limit lower="-0.087267" upper="2.8798" effort="139" velocity="1"/>
        <dynamics damping="0.05" friction="0.2"/>
    </joint>

    <link name="left_knee_link">
        <inertial>
            <origin xyz="0.005457 0.003964 -0.12074" rpy="0 0 0"/>
            <mass value="1.932"/>
            <inertia ixx="0.0113804" ixy="0" ixz="0" iyy="0.0112778" iyz="0" izz="0.00146458"/>
        </inertial>
        <visual>
            <geometry>
                <mesh filename="./meshes/left_knee_link.STL"/>
            </geometry>
            <material name="grey"/>
        </visual>
        <collision>
            <geometry>
                <mesh filename="./meshes/left_knee_link.STL"/>
            </geometry>
        </collision>
    </link>

    <joint name="left_ankle_pitch_joint" type="revolute">
        <parent link="left_knee_link"/>
        <child link="left_ankle_pitch_link"/>
        <origin xyz="0 -9.4445e-05 -0.30001" rpy="0 0 0"/>
        <axis xyz="0 1 0"/>
        <limit lower="-0.87267" upper="0.5236" effort="50" velocity="1"/>
        <dynamics damping="0.05" friction="0.2"/>
    </joint>

    <link name="left_ankle_pitch_link">
        <inertial>
            <origin xyz="-0.007269 0 0.011137" rpy="0 0 0"/>
            <mass value="0.074"/>
            <inertia ixx="1.89e-05" ixy="0" ixz="0" iyy="1.40805e-05" iyz="0" izz="6.9195e-06"/>
        </inertial>
        <visual>
            <geometry>
                <mesh filename="./meshes/left_ankle_pitch_link.STL"/>
            </geometry>
            <material name="grey"/>
        </visual>
        <collision>
            <geometry>
                <mesh filename="./meshes/left_ankle_pitch_link.STL"/>
            </geometry>
        </collision>
    </link>

    <joint name="left_ankle_roll_joint" type="revolute">
        <parent link="left_ankle_pitch_link"/>
        <child link="left_ankle_roll_link"/>
        <origin xyz="0 0 -0.017558" rpy="0 0 0"/>
        <axis xyz="1 0 0"/>
        <limit lower="-0.2618" upper="0.2618" effort="50" velocity="1"/>
        <dynamics damping="0.05" friction="0.2"/>
    </joint>

    <link name="left_ankle_roll_link">
        <inertial>
            <origin xyz="0.026505 0 -0.016425" rpy="0 0 0"/>
            <mass value="0.608"/>
            <inertia ixx="0.00167218" ixy="0" ixz="0" iyy="0.0016161" iyz="0" izz="0.000217621"/>
        </inertial>
        <visual>
            <geometry>
                <mesh filename="./meshes/left_ankle_roll_link.STL"/>
            </geometry>
            <material name="dark_grey"/>
        </visual>
        <collision>
            <geometry>
                <mesh filename="./meshes/left_ankle_roll_link.STL"/>
            </geometry>
        </collision>
    </link>

    <!-- Right Leg -->
    <joint name="right_hip_pitch_joint" type="revolute">
        <parent link="pelvis"/>
        <child link="right_hip_pitch_link"/>
        <origin xyz="0 -0.064452 -0.1027" rpy="0 0 0"/>
        <axis xyz="0 1 0"/>
        <limit lower="-2.5307" upper="2.8798" effort="88" velocity="1"/>
        <dynamics damping="0.05" friction="0.2"/>
    </joint>

    <link name="right_hip_pitch_link">
        <inertial>
            <origin xyz="0.002741 -0.047791 -0.02606" rpy="0 0 0"/>
            <mass value="1.35"/>
            <inertia ixx="0.00181517" ixy="0" ixz="0" iyy="0.00153422" iyz="0" izz="0.00116212"/>
        </inertial>
        <visual>
            <geometry>
                <mesh filename="./meshes/right_hip_pitch_link.STL"/>
            </geometry>
            <material name="dark_grey"/>
        </visual>
        <collision>
            <geometry>
                <mesh filename="./meshes/right_hip_pitch_link.STL"/>
            </geometry>
        </collision>
    </link>

    <joint name="right_hip_roll_joint" type="revolute">
        <parent link="right_hip_pitch_link"/>
        <child link="right_hip_roll_link"/>
        <origin xyz="0 -0.052 -0.030465" rpy="0 -0.0873386 0"/>
        <axis xyz="1 0 0"/>
        <limit lower="-2.9671" upper="0.5236" effort="88" velocity="1"/>
        <dynamics damping="0.05" friction="0.2"/>
    </joint>

    <link name="right_hip_roll_link">
        <inertial>
            <origin xyz="0.029812 0.001045 -0.087934" rpy="0 0 0"/>
            <mass value="1.52"/>
            <inertia ixx="0.00254986" ixy="0" ixz="0" iyy="0.00241169" iyz="0" izz="0.00148755"/>
        </inertial>
        <visual>
            <geometry>
                <mesh filename="./meshes/right_hip_roll_link.STL"/>
            </geometry>
            <material name="grey"/>
        </visual>
        <collision>
            <geometry>
                <mesh filename="./meshes/right_hip_roll_link.STL"/>
            </geometry>
        </collision>
    </link>

    <joint name="right_hip_yaw_joint" type="revolute">
        <parent link="right_hip_roll_link"/>
        <child link="right_hip_yaw_link"/>
        <origin xyz="0.025001 0 -0.12412" rpy="0 0 0"/>
        <axis xyz="0 0 1"/>
        <limit lower="-2.7576" upper="2.7576" effort="88" velocity="1"/>
        <dynamics damping="0.05" friction="0.2"/>
    </joint>

    <link name="right_hip_yaw_link">
        <inertial>
            <origin xyz="-0.057709 0.010981 -0.15078" rpy="0 0 0"/>
            <mass value="1.702"/>
            <inertia ixx="0.00776166" ixy="0" ixz="0" iyy="0.00717575" iyz="0" izz="0.00160139"/>
        </inertial>
        <visual>
            <geometry>
                <mesh filename="./meshes/right_hip_yaw_link.STL"/>
            </geometry>
            <material name="grey"/>
        </visual>
        <collision>
            <geometry>
                <mesh filename="./meshes/right_hip_yaw_link.STL"/>
            </geometry>
        </collision>
    </link>

    <joint name="right_knee_joint" type="revolute">
        <parent link="right_hip_yaw_link"/>
        <child link="right_knee_link"/>
        <origin xyz="-0.078273 -0.0021489 -0.17734" rpy="0 0.0873386 0"/>
        <axis xyz="0 1 0"/>
        <limit lower="-0.087267" upper="2.8798" effort="139" velocity="1"/>
        <dynamics damping="0.05" friction="0.2"/>
    </joint>

    <link name="right_knee_link">
        <inertial>
            <origin xyz="0.005457 -0.003964 -0.12074" rpy="0 0 0"/>
            <mass value="1.932"/>
            <inertia ixx="0.011374" ixy="0" ixz="0" iyy="0.0112843" iyz="0" izz="0.00146452"/>
        </inertial>
        <visual>
            <geometry>
                <mesh filename="./meshes/right_knee_link.STL"/>
            </geometry>
            <material name="grey"/>
        </visual>
        <collision>
            <geometry>
                <mesh filename="./meshes/right_knee_link.STL"/>
            </geometry>
        </collision>
    </link>

    <joint name="right_ankle_pitch_joint" type="revolute">
        <parent link="right_knee_link"/>
        <child link="right_ankle_pitch_link"/>
        <origin xyz="0 9.4445e-05 -0.30001" rpy="0 0 0"/>
        <axis xyz="0 1 0"/>
        <limit lower="-0.87267" upper="0.5236" effort="50" velocity="1"/>
        <dynamics damping="0.05" friction="0.2"/>
    </joint>

    <link name="right_ankle_pitch_link">
        <inertial>
            <origin xyz="-0.007269 0 0.011137" rpy="0 0 0"/>
            <mass value="0.074"/>
            <inertia ixx="1.89e-05" ixy="0" ixz="0" iyy="1.40805e-05" iyz="0" izz="6.9195e-06"/>
        </inertial>
        <visual>
            <geometry>
                <mesh filename="./meshes/right_ankle_pitch_link.STL"/>
            </geometry>
            <material name="grey"/>
        </visual>
        <collision>
            <geometry>
                <mesh filename="./meshes/right_ankle_pitch_link.STL"/>
            </geometry>
        </collision>
    </link>

    <joint name="right_ankle_roll_joint" type="revolute">
        <parent link="right_ankle_pitch_link"/>
        <child link="right_ankle_roll_link"/>
        <origin xyz="0 0 -0.017558" rpy="0 0 0"/>
        <axis xyz="1 0 0"/>
        <limit lower="-0.2618" upper="0.2618" effort="50" velocity="1"/>
        <dynamics damping="0.05" friction="0.2"/>
    </joint>

    <link name="right_ankle_roll_link">
        <inertial>
            <origin xyz="0.026505 0 -0.016425" rpy="0 0 0"/>
            <mass value="0.608"/>
            <inertia ixx="0.00167218" ixy="0" ixz="0" iyy="0.0016161" iyz="0" izz="0.000217621"/>
        </inertial>
        <visual>
            <geometry>
                <mesh filename="./meshes/right_ankle_roll_link.STL"/>
            </geometry>
            <material name="dark_grey"/>
        </visual>
        <collision>
            <geometry>
                <mesh filename="./meshes/right_ankle_roll_link.STL"/>
            </geometry>
        </collision>
    </link>

    <!-- Torso -->
    <joint name="waist_yaw_joint" type="revolute">
        <parent link="pelvis"/>
        <child link="torso_link"/>
        <origin xyz="-0.0039635 0 0.054" rpy="0 0 0"/>
        <axis xyz="0 0 1"/>
        <limit lower="-2.618" upper="2.618" effort="88" velocity="1"/>
        <dynamics damping="0.05" friction="0.2"/>
    </joint>

    <link name="torso_link">
        <inertial>
            <origin xyz="0.0034309 0.00025505 0.174524" rpy="0 0 0"/>
            <mass value="9.842"/>
            <inertia ixx="0.135151" ixy="0" ixz="0" iyy="0.123088" iyz="0" izz="0.0327256"/>
        </inertial>
        <visual>
            <geometry>
                <mesh filename="./meshes/torso_link.STL"/>
            </geometry>
            <material name="grey"/>
        </visual>
        <visual>
            <origin xyz="0.0039635 0 -0.054" rpy="0 0 0"/>
            <geometry>
                <mesh filename="./meshes/waist_yaw_link.STL"/>
            </geometry>
            <material name="grey"/>
        </visual>
        <visual>
            <origin xyz="0.0039635 0 -0.054" rpy="0 0 0"/>
            <geometry>
                <mesh filename="./meshes/logo_link.STL"/>
            </geometry>
            <material name="dark_grey"/>
        </visual>
        <visual>
            <origin xyz="0.0039635 0 -0.054" rpy="0 0 0"/>
            <geometry>
                <mesh filename="./meshes/head_link.STL"/>
            </geometry>
            <material name="dark_grey"/>
        </visual>
        <visual>
            <origin xyz="0.0039635 0 -0.054" rpy="0 0 0"/>
            <geometry>
                <mesh filename="./meshes/waist_support_link.STL"/>
            </geometry>
            <material name="grey"/>
        </visual>
        <collision>
            <geometry>
                <mesh filename="./meshes/torso_link.STL"/>
            </geometry>
        </collision>
    </link>

    <!-- Left Arm -->
    <joint name="left_shoulder_pitch_joint" type="revolute">
        <parent link="torso_link"/>
        <child link="left_shoulder_pitch_link"/>
        <origin xyz="0.0039563 0.10022 0.23778" rpy="0 0.139201 0"/>
        <axis xyz="0 1 0"/>
        <limit lower="-3.0892" upper="2.6704" effort="25" velocity="1"/>
        <dynamics damping="0.05" friction="0.2"/>
    </joint>

    <link name="left_shoulder_pitch_link">
        <inertial>
            <origin xyz="0 0.035892 -0.011628" rpy="0 0 0"/>
            <mass value="0.718"/>
            <inertia ixx="0.000465864" ixy="0" ixz="0" iyy="0.000432842" iyz="0" izz="0.000406394"/>
        </inertial>
        <visual>
            <geometry>
                <mesh filename="./meshes/left_shoulder_pitch_link.STL"/>
            </geometry>
            <material name="grey"/>
        </visual>
        <collision>
            <geometry>
                <mesh filename="./meshes/left_shoulder_pitch_link.STL"/>
            </geometry>
        </collision>
    </link>

    <joint name="left_shoulder_roll_joint" type="revolute">
        <parent link="left_shoulder_pitch_link"/>
        <child link="left_shoulder_roll_link"/>
        <origin xyz="0 0.038 -0.013831" rpy="0 -0.139172 0"/>
        <axis xyz="1 0 0"/>
        <limit lower="-1.5882" upper="2.2515" effort="25" velocity="1"/>
        <dynamics damping="0.05" friction="0.2"/>
    </joint>

    <link name="left_shoulder_roll_link">
        <inertial>
            <origin xyz="-0.000227 0.00727 -0.063243" rpy="0 0 0"/>
            <mass value="0.643"/>
            <inertia ixx="0.000691311" ixy="0" ixz="0" iyy="0.000618011" iyz="0" izz="0.000388977"/>
        </inertial>
        <visual>
            <geometry>
                <mesh filename="./meshes/left_shoulder_roll_link.STL"/>
            </geometry>
            <material name="grey"/>
        </visual>
        <collision>
            <geometry>
                <mesh filename="./meshes/left_shoulder_roll_link.STL"/>
            </geometry>
        </collision>
    </link>

    <joint name="left_shoulder_yaw_joint" type="revolute">
        <parent link="left_shoulder_roll_link"/>
        <child link="left_shoulder_yaw_link"/>
        <origin xyz="0 0.00624 -0.1032" rpy="0 0 0"/>
        <axis xyz="0 0 1"/>
        <limit lower="-2.618" upper="2.618" effort="25" velocity="1"/>
        <dynamics damping="0.05" friction="0.2"/>
    </joint>

    <link name="left_shoulder_yaw_link">
        <inertial>
            <origin xyz="0.010773 -0.002949 -0.072009" rpy="0 0 0"/>
            <mass value="0.734"/>
            <inertia ixx="0.00106187" ixy="0" ixz="0" iyy="0.00103217" iyz="0" izz="0.000400661"/>
        </inertial>
        <visual>
            <geometry>
                <mesh filename="./meshes/left_shoulder_yaw_link.STL"/>
            </geometry>
            <material name="grey"/>
        </visual>
        <collision>
            <geometry>
                <mesh filename="./meshes/left_shoulder_yaw_link.STL"/>
            </geometry>
        </collision>
    </link>

    <joint name="left_elbow_joint" type="revolute">
        <parent link="left_shoulder_yaw_link"/>
        <child link="left_elbow_link"/>
        <origin xyz="0.015783 0 -0.080518" rpy="0 0 0"/>
        <axis xyz="0 1 0"/>
        <limit lower="-1.0472" upper="2.0944" effort="25" velocity="1"/>
        <dynamics damping="0.05" friction="0.2"/>
    </joint>

    <link name="left_elbow_link">
        <inertial>
            <origin xyz="0.064956 0.004454 -0.010062" rpy="0 0 0"/>
            <mass value="0.6"/>
            <inertia ixx="0.000443035" ixy="0" ixz="0" iyy="0.000421612" iyz="0" izz="0.000259353"/>
        </inertial>
        <visual>
            <geometry>
                <mesh filename="./meshes/left_elbow_link.STL"/>
            </geometry>
            <material name="grey"/>
        </visual>
        <collision>
            <geometry>
                <mesh filename="./meshes/left_elbow_link.STL"/>
            </geometry>
        </collision>
    </link>

    <joint name="left_wrist_roll_joint" type="revolute">
        <parent link="left_elbow_link"/>
        <child link="left_wrist_roll_link"/>
        <origin xyz="0.1 0.00188791 -0.01" rpy="0 0 0"/>
        <axis xyz="1 0 0"/>
        <limit lower="-1.97222" upper="1.97222" effort="25" velocity="1"/>
        <dynamics damping="0.05" friction="0.2"/>
    </joint>

    <link name="left_wrist_roll_link">
        <inertial>
            <origin xyz="0.107947 0.00163512 0.00202245" rpy="0 0 0"/>
            <mass value="0.356929"/>
            <inertia ixx="0.00200292" ixy="0" ixz="0" iyy="0.0019426" iyz="0" izz="0.000195232"/>
        </inertial>
        <visual>
            <geometry>
                <mesh filename="./meshes/left_wrist_roll_rubber_hand.STL"/>
            </geometry>
            <material name="grey"/>
        </visual>
        <collision>
            <geometry>
                <mesh filename="./meshes/left_wrist_roll_rubber_hand.STL"/>
            </geometry>
        </collision>
    </link>

    <!-- Right Arm -->
    <joint name="right_shoulder_pitch_joint" type="revolute">
        <parent link="torso_link"/>
        <child link="right_shoulder_pitch_link"/>
        <origin xyz="0.0039563 -0.10021 0.23778" rpy="0 -0.139201 0"/>
        <axis xyz="0 1 0"/>
        <limit lower="-3.0892" upper="2.6704" effort="25" velocity="1"/>
        <dynamics damping="0.05" friction="0.2"/>
    </joint>

    <link name="right_shoulder_pitch_link">
        <inertial>
            <origin xyz="0 -0.035892 -0.011628" rpy="0 0 0"/>
            <mass value="0.718"/>
            <inertia ixx="0.000465864" ixy="0" ixz="0" iyy="0.000432842" iyz="0" izz="0.000406394"/>
        </inertial>
        <visual>
            <geometry>
                <mesh filename="./meshes/right_shoulder_pitch_link.STL"/>
            </geometry>
            <material name="grey"/>
        </visual>
        <collision>
            <geometry>
                <mesh filename="./meshes/right_shoulder_pitch_link.STL"/>
            </geometry>
        </collision>
    </link>

    <joint name="right_shoulder_roll_joint" type="revolute">
        <parent link="right_shoulder_pitch_link"/>
        <child link="right_shoulder_roll_link"/>
        <origin xyz="0 -0.038 -0.013831" rpy="0 0.139172 0"/>
        <axis xyz="1 0 0"/>
        <limit lower="-2.2515" upper="1.5882" effort="25" velocity="1"/>
        <dynamics damping="0.05" friction="0.2"/>
    </joint>

    <link name="right_shoulder_roll_link">
        <inertial>
            <origin xyz="-0.000227 -0.00727 -0.063243" rpy="0 0 0"/>
            <mass value="0.643"/>
            <inertia ixx="0.000691311" ixy="0" ixz="0" iyy="0.000618011" iyz="0" izz="0.000388977"/>
        </inertial>
        <visual>
            <geometry>
                <mesh filename="./meshes/right_shoulder_roll_link.STL"/>
            </geometry>
            <material name="grey"/>
        </visual>
        <collision>
            <geometry>
                <mesh filename="./meshes/right_shoulder_roll_link.STL"/>
            </geometry>
        </collision>
    </link>

    <joint name="right_shoulder_yaw_joint" type="revolute">
        <parent link="right_shoulder_roll_link"/>
        <child link="right_shoulder_yaw_link"/>
        <origin xyz="0 -0.00624 -0.1032" rpy="0 0 0"/>
        <axis xyz="0 0 1"/>
        <limit lower="-2.618" upper="2.618" effort="25" velocity="1"/>
        <dynamics damping="0.05" friction="0.2"/>
    </joint>

    <link name="right_shoulder_yaw_link">
        <inertial>
            <origin xyz="0.010773 0.002949 -0.072009" rpy="0 0 0"/>
            <mass value="0.734"/>
            <inertia ixx="0.00106187" ixy="0" ixz="0" iyy="0.00103217" iyz="0" izz="0.000400661"/>
        </inertial>
        <visual>
            <geometry>
                <mesh filename="./meshes/right_shoulder_yaw_link.STL"/>
            </geometry>
            <material name="grey"/>
        </visual>
        <collision>
            <geometry>
                <mesh filename="./meshes/right_shoulder_yaw_link.STL"/>
            </geometry>
        </collision>
    </link>

    <joint name="right_elbow_joint" type="revolute">
        <parent link="right_shoulder_yaw_link"/>
        <child link="right_elbow_link"/>
        <origin xyz="0.015783 0 -0.080518" rpy="0 0 0"/>
        <axis xyz="0 1 0"/>
        <limit lower="-1.0472" upper="2.0944" effort="25" velocity="1"/>
        <dynamics damping="0.05" friction="0.2"/>
    </joint>

    <link name="right_elbow_link">
        <inertial>
            <origin xyz="0.064956 -0.004454 -0.010062" rpy="0 0 0"/>
            <mass value="0.6"/>
            <inertia ixx="0.000443035" ixy="0" ixz="0" iyy="0.000421612" iyz="0" izz="0.000259353"/>
        </inertial>
        <visual>
            <geometry>
                <mesh filename="./meshes/right_elbow_link.STL"/>
            </geometry>
            <material name="grey"/>
        </visual>
        <collision>
            <geometry>
                <mesh filename="./meshes/right_elbow_link.STL"/>
            </geometry>
        </collision>
    </link>

    <joint name="right_wrist_roll_joint" type="revolute">
        <parent link="right_elbow_link"/>
        <child link="right_wrist_roll_link"/>
        <origin xyz="0.1 -0.00188791 -0.01" rpy="0 0 0"/>
        <axis xyz="1 0 0"/>
        <limit lower="-1.97222" upper="1.97222" effort="25" velocity="1"/>
        <dynamics damping="0.05" friction="0.2"/>
    </joint>

    <link name="right_wrist_roll_link">
        <inertial>
            <origin xyz="0.107947 -0.00163512 0.00202245" rpy="0 0 0"/>
            <mass value="0.356929"/>
            <inertia ixx="0.00200292" ixy="0" ixz="0" iyy="0.0019426" iyz="0" izz="0.000195232"/>
        </inertial>
        <visual>
            <geometry>
                <mesh filename="./meshes/right_wrist_roll_rubber_hand.STL"/>
            </geometry>
            <material name="grey"/>
        </visual>
        <collision>
            <geometry>
                <mesh filename="./meshes/right_wrist_roll_rubber_hand.STL"/>
            </geometry>
        </collision>
    </link>

    <!-- IMU -->
    <joint name="imu_joint" type="fixed">
        <parent link="torso_link"/>
        <child link="imu_link"/>
        <origin xyz="-0.03959 -0.00224 0.13792" rpy="0 0 0"/>
    </joint>

    <link name="imu_link">
        <inertial>
            <mass value="0.001"/>
            <inertia ixx="0.0001" ixy="0" ixz="0" iyy="0.0001" iyz="0" izz="0.0001"/>
        </inertial>
    </link>

</robot> 